Workbook

Sheet satker q
A2: LAPORAN SISA KAS
A3: SATKER ……………………… (1)
A4: BULAN ……..…………….. (2)
A6: No | B6: Rekening | F6: Pencairan Dana | J6: Jumlah Sisa Kas | K6: Nama Kontrak Tgl. Berakhir | L6: Nilai | M6: SP2D-Sisa
B7: Nama | C7: Nomor | D7: Mata Uang | E7: Bank | F7: UP Tunai | G7: GUP | H7: LS Bendahara | I7: TUP
A8: 1 | B8: 2 | C8: 3 | D8: 4 | E8: 5 | F8: 6 | G8: 7 | H8: 8 | I8: 9 | J8: 10 | K8: 14 | L8: 15 | M8: 16
A9: A | B9: Rekening Rutin
A10: 1 | B10: BPG 019 Baranahan | C10: 1230000000 | D10: IDR | E10: Bank xxx | F10: xxx.xxx | G10: xxx.xxx | H10: xxx.xxxx | I10: xxx.xxx | J10: xxx.xxx
A11: dst
A13: B | B13: Rekening Pemerintah Lainnya (Hibah,BLU dan Lainnya)
A14: 1 | B14: RPL 019 PDH xxxxx untuk 1234567 | C14: 1230000000 | D14: IDR | E14: Bank xxx | F14: - | G14: - | H14: - | I14: - | J14: xxx.xxx
A16: 2 | B16: RPL 019 KS Baranahan Kemhan untuk Kontrak DSME | C16: 1230000000 | D16: USD | E16: Bank xxx | F16: - | G16: - | H16: - | I16: - | J16: xxx.xxx
A17: dst
A19: (3) | B19: (4) | C19: (5) | D19: (6) | E19: (7) | F19: (8) | G19: (9) | H19: (10) | I19: (11) | J19: (12) | K19: (14)
B22: JUMLAH (13) | F22: RP | G22: RP | H22: RP | I22: RP | J22: RP
F23: USD | G23: USD | H23: USD | I23: USD | J23: USD
K24: KPA/PPSPM/Kepala Satuan Kerja
I25: Bendahara Pengeluaran,
K28: Pangkat NRP/NIP
I29: Nama
I30: Pangkat NRP/NIP

Sheet SATKER
A5: LAPORAN SISA KAS
A6: SATKER ……………………… (1)
A7: BULAN ……..…………….. (2)
A9: No | B9: Rekening | F9: Pencairan Dana | J9: Surat Persetujuan | L9: Tanggal Transaksi Terakhir | M9: Saldo Akhir Bank | N9: Nama Kontrak Tgl. Berakhir | O9: Nilai | P9: SP2D-Sisa
B10: Nama | C10: Nomor | D10: Mata Uang | E10: Bank | F10: UP Tunai | G10: GUP | H10: LS Bendahara | I10: TUP | J10: Nomor | K10: Tanggal
A11: 1 | B11: 2 | C11: 3 | D11: 4 | E11: 5 | F11: 6 | G11: 7 | H11: 8 | I11: 9 | J11: 10 | K11: 11 | L11: 12 | M11: 13=6+7+8+9 | N11: 14 | O11: 15 | P11: 16
A12: A | B12: Rekening Rutin
A13: 1 | B13: BPG xxx Baranahan
A15: B | B15: Rekening Pemerintah Lainnya (Hibah,BLU dan Lainnya)
A16: 1 | B16: RPL xxx PDH 684044 untuk xxxxxxxx (Nomor Reg Hibah)
A18: 2 | B18: RPL xxx KS Baranahan Kemhan untuk Kontrak DSME
A21: (3) | B21: (4) | C21: (5) | D21: (6) | E21: (7) | F21: (8) | G21: (9) | H21: (10) | I21: (11) | J21: (12) | K21: (13) | L21: (14) | M21: (15) | N21: (14)
B24: JUMLAH (16) | M24: RP
M25: USD
N26: KPA/PPSPM/Kepala Satuan Kerja
K27: Paku TNI Wilayah xxxx
N30: Pangkat NRP/NIP
K32: Nama
K33: Pangkat NRP/NIP

Sheet BABEK
A5: LAPORAN SISA KAS
A6: SATKER BABEK TNI
A7: BULAN JULI
A9: No | B9: Rekening | F9: Pencairan Dana | J9: Surat Persetujuan | L9: Tanggal Transaksi Terakhir | M9: Saldo Akhir Bank
B10: Nama | C10: Nomor | D10: Mata Uang | E10: Bank | F10: UP Tunai | G10: GUP | H10: LS Bendahara | I10: TUP | J10: Nomor | K10: Tanggal
A11: 1 | B11: 2 | C11: 3 | D11: 4 | E11: 5 | F11: 6 | G11: 7 | H11: 8 | I11: 9 | J11: 10 | K11: 11 | L11: 12 | M11: 13=6+7+8+9
A12: A | B12: Rekening Rutin
A13: 1 | B13: BPG 086 BABEK TNI | C13: 8.1001268e+15 | D13: Rupiah Murni | E13: Mandiri | H13: 81368200 | J13: 000311 | K13: 44546 | L13: 45869 | M13: NIHIL
A15: B | B15: Rekening Pemerintah Lainnya (Hibah,BLU dan Lainnya)
A16: 1 | B16: RPL xxx PDH 684044 untuk xxxxxxxx (Nomor Reg Hibah)
A18: 2 | B18: RPL xxx KS Baranahan Kemhan untuk Kontrak DSME
A21: (3) | B21: (4) | C21: (5) | D21: (6) | E21: (7) | F21: (8) | G21: (9) | H21: (10) | I21: (11) | J21: (12) | K21: (13) | L21: (14) | M21: (15)
B24: JUMLAH (16) | M24: =SUM(M12:M20) -> 0
M25: USD
K27: Paku TNI Wilayah VI
K32: Luqman Hakim
K33: Mayor Cku NRP 21960362020574

Sheet PUSKES
A5: LAPORAN SISA KAS
A6: SATKER PUSKES TNI
A7: BULAN JULI 2025
A9: No | B9: Rekening | F9: Pencairan Dana | J9: Surat Persetujuan | L9: Tanggal Transaksi Terakhir | M9: Saldo Akhir Bank
B10: Nama | C10: Nomor | D10: Mata Uang | E10: Bank | F10: UP Tunai | G10: GUP | H10: LS Bendahara | I10: TUP | J10: Nomor | K10: Tanggal
A11: 1 | B11: 2 | C11: 3 | D11: 4 | E11: 5 | F11: 6 | G11: 7 | H11: 8 | I11: 9 | J11: 10 | K11: 11 | L11: 12 | M11: 13=6+7+8+9
A12: A | B12: Rekening Rutin
A13: 1 | B13: BPG 088 PUSKES TNI | C13: 8.1001268e+15 | D13: Rupiah Murni | E13: Mandiri | F13: 0 | G13: 0 | H13: 42498039 | I13: 0 | J13: 000313 | K13: 44546 | L13: 45867 | M13: 0
A15: B | B15: Rekening Pemerintah Lainnya (Hibah,BLU dan Lainnya)
A16: 1 | B16: RPL xxx PDH 684044 untuk xxxxxxxx (Nomor Reg Hibah)
A18: 2 | B18: RPL xxx KS Baranahan Kemhan untuk Kontrak DSME
A21: (3) | B21: (4) | C21: (5) | D21: (6) | E21: (7) | F21: (8) | G21: (9) | H21: (10) | I21: (11) | J21: (12) | K21: (13) | L21: (14) | M21: (15)
B24: JUMLAH (16) | M24: =SUM(M13:M20) -> 0
M25: USD
K27: Paku TNI Wilayah VII
K32: Yulianis, S.E.
K33: Mayor Cku (K) NRP 21940142760971

Sheet PUSPSI
A5: LAPORAN SISA KAS
A6: SATKER PUSPSI TNI
A7: BULAN JULI 2025
A9: No | B9: Rekening | F9: Pencairan Dana | J9: Surat Persetujuan | L9: Tanggal Transaksi Terakhir | M9: Saldo Akhir Bank
B10: Nama | C10: Nomor | D10: Mata Uang | E10: Bank | F10: UP Tunai | G10: GUP | H10: LS Bendahara | I10: TUP | J10: Nomor | K10: Tanggal
A11: 1 | B11: 2 | C11: 3 | D11: 4 | E11: 5 | F11: 6 | G11: 7 | H11: 8 | I11: 9 | J11: 10 | K11: 11 | L11: 12 | M11: 13=6+7+8+9
A12: A | B12: Rekening Rutin
A13: 1 | B13: BPG 088 PUSPSI TNI | C13: 8.1001234e+15 | D13: Rupiah Murni | E13: Mandiri | F13: 0 | G13: 0 | H13: 0 | I13: 0 | J13: S-3573/KPN.1201/2022 | K13: 44917 | L13: 45869 | M13: 0
A15: B | B15: Rekening Pemerintah Lainnya (Hibah,BLU dan Lainnya)
A16: 1 | B16: RPL xxx PDH 684044 untuk xxxxxxxx (Nomor Reg Hibah)
A18: 2 | B18: RPL xxx KS Baranahan Kemhan untuk Kontrak DSME
A21: (3) | B21: (4) | C21: (5) | D21: (6) | E21: (7) | F21: (8) | G21: (9) | H21: (10) | I21: (11) | J21: (12) | K21: (13) | L21: (14) | M21: (15)
B24: JUMLAH (16) | M24: =SUM(M13:M19) -> 0
M25: USD
K27: Paku TNI Wilayah VII
K32: Yulianis, S.E.
K33: Mayor Cku (K) NRP 21940142760971

Sheet BAIS
A5: LAPORAN SISA KAS
A6: SATKER BAIS TNI
A7: BULAN JULI 2025
A9: No | B9: Rekening | F9: Pencairan Dana | J9: Surat Persetujuan | L9: Tanggal Transaksi Terakhir | M9: Saldo Akhir Bank
B10: Nama | C10: Nomor | D10: Mata Uang | E10: Bank | F10: UP Tunai | G10: GUP | H10: LS Bendahara | I10: TUP | J10: Nomor | K10: Tanggal
A11: 1 | B11: 2 | C11: 3 | D11: 4 | E11: 5 | F11: 6 | G11: 7 | H11: 8 | I11: 9 | J11: 10 | K11: 11 | L11: 12 | M11: 13=6+7+8+9
A12: A | B12: Rekening Rutin
A13: 1 | B13: BPG 019 Bais TNI | C13: 8.1001268e+15 | D13: IDR | E13: MANDIRI | F13: 40000000000 | G13: 61838666657 | H13: 21483352530 | I13: 0 | J13: S-3034/WPB.12/KP.01/2020 | K13: 44140 | L13: 45861 | M13: 6472863317
A15: B | B15: Rekening Pemerintah Lainnya (Hibah,BLU dan Lainnya)
A16: 1 | B16: RPL xxx PDH 684044 untuk xxxxxxxx (Nomor Reg Hibah)
A18: 2 | B18: RPL xxx KS Baranahan Kemhan untuk Kontrak DSME
A21: (3) | B21: (4) | C21: (5) | D21: (6) | E21: (7) | F21: (8) | G21: (9) | H21: (10) | I21: (11) | J21: (12) | K21: (13) | L21: (14) | M21: (15)
B24: JUMLAH (16) | M24: RP
M25: USD
K27: Paku TNI Wilayah VIII
K32: Dading Yudis H, S.E., M.Ap., M.Tr. Opsla
K33: Mayor Laut (S) NRp 18760/P

Sheet MAKO AKADEMI
A5: LAPORAN SISA KAS
A6: SATKER MAKO AKADEMI TNI
A7: BULAN JULI 2025
A9: No | B9: Rekening | F9: Pencairan Dana | J9: Surat Persetujuan | L9: Tanggal Transaksi Terakhir | M9: Saldo Akhir Bank
B10: Nama | C10: Nomor | D10: Mata Uang | E10: Bank | F10: UP Tunai | G10: GUP | H10: LS Bendahara | I10: TUP | J10: Nomor | K10: Tanggal
A11: 1 | B11: 2 | C11: 3 | D11: 4 | E11: 5 | F11: 6 | G11: 7 | H11: 8 | I11: 9 | J11: 10 | K11: 11 | L11: 12 | M11: 13=6+7+8+9
A12: A | B12: Rekening Rutin
A13: 1 | B13: BPG 088 Akademi TNI | C13: 8.1001268e+15 | D13: IDR | E13: Mandiri | F13: 0 | G13: 0 | H13: 387181048 | I13: 0 | J13: S-3034/WPB.12/KP.01/2020 | K13: 44140 | L13: 45862 | M13: 0
A15: B | B15: Rekening Pemerintah Lainnya (Hibah,BLU dan Lainnya)
A16: 1 | B16: RPL xxx PDH 684044 untuk xxxxxxxx (Nomor Reg Hibah)
A18: 2 | B18: RPL xxx KS Baranahan Kemhan untuk Kontrak DSME
A21: (3) | B21: (4) | C21: (5) | D21: (6) | E21: (7) | F21: (8) | G21: (9) | H21: (10) | I21: (11) | J21: (12) | K21: (13) | L21: (14) | M21: (15)
B24: JUMLAH (16) | M24: =SUM(M13:M19) -> 0
M25: USD
K27: Paku TNI Wilayah IX
K32: I Wayan Eka Sunartha, S.E., M.M.
K33: Letkol Cku NRP 11040002431276

Sheet PUSKU
A5: LAPORAN SISA KAS
A6: SATKER PUSKU TNI
A7: BULAN JULI 2025
A9: No | B9: Rekening | F9: Pencairan Dana | J9: Surat Persetujuan | L9: Tanggal Transaksi Terakhir | M9: Saldo Akhir Bank
B10: Nama | C10: Nomor | D10: Mata Uang | E10: Bank | F10: UP Tunai | G10: GUP | H10: LS Bendahara | I10: TUP | J10: Nomor | K10: Tanggal
A11: 1 | B11: 2 | C11: 3 | D11: 4 | E11: 5 | F11: 6 | G11: 7 | H11: 8 | I11: 9 | J11: 10 | K11: 11 | L11: 12 | M11: 13=6+7+8+9
A12: A | B12: Rekening Rutin
A13: 1 | B13: BPG 088 Pusku TNI | C13: 8.1001268e+15 | D13: IDR | E13: Mandiri | F13: 0 | G13: 0 | H13: 402818432 | I13: 0 | J13: S-3034/WPB.12/KP.01/2020 | K13: 44140 | L13: - | M13: 0
A15: B | B15: Rekening Pemerintah Lainnya (Hibah,BLU dan Lainnya)
A16: 1 | B16: RPL xxx PDH 684044 untuk xxxxxxxx (Nomor Reg Hibah)
A18: 2 | B18: RPL xxx KS Baranahan Kemhan untuk Kontrak DSME
A21: (3) | B21: (4) | C21: (5) | D21: (6) | E21: (7) | F21: (8) | G21: (9) | H21: (10) | I21: (11) | J21: (12) | K21: (13) | L21: (14) | M21: (15)
B24: JUMLAH (16) | M24: RP
M25: USD
K27: Paku TNI Wilayah IX
K32: I Wayan Eka Sunartha, S.E., M.M
K33: Letkol Cku NRP 11040002431276

Sheet PUSPEN
A5: LAPORAN SISA KAS
A6: SATKER PUSPEN TNI
A7: BULAN JULI 2025
A9: No | B9: Rekening | F9: Pencairan Dana | J9: Surat Persetujuan | L9: Tanggal Transaksi Terakhir | M9: Saldo Akhir Bank
B10: Nama | C10: Nomor | D10: Mata Uang | E10: Bank | F10: UP Tunai | G10: GUP | H10: LS Bendahara | I10: TUP | J10: Nomor | K10: Tanggal
A11: 1 | B11: 2 | C11: 3 | D11: 4 | E11: 5 | F11: 6 | G11: 7 | H11: 8 | I11: 9 | J11: 10 | K11: 11 | L11: 12 | M11: 13=6+7+8+9
A12: A | B12: Rekening Rutin
A13: 1 | B13: BPG 088 Puspen TNI | C13: 8.1001268e+15 | D13: IDR | E13: Mandiri | F13: 0 | G13: 0 | H13: 38670000 | I13: 0 | J13: S-3034/WPB,12/KP,01/2020 | K13: 44137 | L13: 45868 | M13: 0
A15: B | B15: Rekening Pemerintah Lainnya (Hibah,BLU dan Lainnya)
A16: 1 | B16: RPL xxx PDH 684044 untuk xxxxxxxx (Nomor Reg Hibah)
A18: 2 | B18: RPL xxx KS Baranahan Kemhan untuk Kontrak DSME
A21: (3) | B21: (4) | C21: (5) | D21: (6) | E21: (7) | F21: (8) | G21: (9) | H21: (10) | I21: (11) | J21: (12) | K21: (13) | L21: (14) | M21: (15)
B24: JUMLAH (16) | M24: =SUM(M13:M19) -> 0
M25: USD
K27: Paku TNI Wilayah IX
K32: I Wayan Eka Sunartha, S.E., M.M.
K33: Letkol Cku NRP 11040002431276

Sheet PUSDALOPS
A5: LAPORAN SISA KAS
A6: SATKER PUSDALOPS TNI
A7: BULAN JULI 2025
A9: No | B9: Rekening | F9: Pencairan Dana | J9: Surat Persetujuan | L9: Tanggal Transaksi Terakhir | M9: Saldo Akhir Bank
B10: Nama | C10: Nomor | D10: Mata Uang | E10: Bank | F10: UP Tunai | G10: GUP | H10: LS Bendahara | I10: TUP | J10: Nomor | K10: Tanggal
A11: 1 | B11: 2 | C11: 3 | D11: 4 | E11: 5 | F11: 6 | G11: 7 | H11: 8 | I11: 9 | J11: 10 | K11: 11 | L11: 12 | M11: 13=6+7+8+9
A12: A | B12: Rekening Rutin
A13: 1 | B13: BPG 088 Pusdalops TNI | C13: 8.1001268e+15 | D13: IDR | E13: Mandiri | F13: 0 | G13: 0 | H13: 52478500 | I13: 0 | J13: S-3034/wpb,12/kp.01/2020 | K13: 44140 | L13: 45866 | M13: 0
A15: B | B15: Rekening Pemerintah Lainnya (Hibah,BLU dan Lainnya)
A16: 1 | B16: RPL xxx PDH 684044 untuk xxxxxxxx (Nomor Reg Hibah)
A18: 2 | B18: RPL xxx KS Baranahan Kemhan untuk Kontrak DSME
A21: (3) | B21: (4) | C21: (5) | D21: (6) | E21: (7) | F21: (8) | G21: (9) | H21: (10) | I21: (11) | J21: (12) | K21: (13) | L21: (14) | M21: (15)
B24: JUMLAH (16) | M24: RP
M25: USD
K27: Paku TNI Wilayah IX
K32: I Wayan Eka Sunartha, S.E., M.M.
K33: Letkol Cku NRP 11040002431276

Sheet PASPAMPRES
A5: LAPORAN SISA KAS
A6: SATKER PASPAMPRES
A7: BULAN JULI 2025
A9: No | B9: Rekening | F9: Pencairan Dana | J9: Surat Persetujuan | L9: Tanggal Transaksi Terakhir | M9: Saldo Akhir Bank
B10: Nama | C10: Nomor | D10: Mata Uang | E10: Bank | F10: UP Tunai | G10: GUP | H10: LS Bendahara | I10: TUP | J10: Nomor | K10: Tanggal
A11: 1 | B11: 2 | C11: 3 | D11: 4 | E11: 5 | F11: 6 | G11: 7 | H11: 8 | I11: 9 | J11: 10 | K11: 11 | L11: 12 | M11: 13=6+7+8+9
A12: A | B12: Rekening Rutin | K12: {=K12:L19} -> 0
A13: 1 | B13: BPG 019 PASPAMPRES | C13: 8.1001268e+15 | D13: Rupiah Murni | E13: Mandiri | H13: 135556104 | J13: S-3034/WPB.12/KP.01/2020 | K13: 44140 | L13: 45867 | M13: 0
A15: B | B15: Rekening Pemerintah Lainnya (Hibah,BLU dan Lainnya)
A16: 1 | B16: RPL xxx PDH 684044 untuk xxxxxxxx (Nomor Reg Hibah)
A18: 2 | B18: RPL xxx KS Baranahan Kemhan untuk Kontrak DSME
A21: (3) | B21: (4) | C21: (5) | D21: (6) | E21: (7) | F21: (8) | G21: (9) | H21: (10) | I21: (11) | J21: (12) | K21: (13) | L21: (14) | M21: (15)
B24: JUMLAH (16) | M24: RP
M25: USD
K27: Paku TNI Wilayah X
K32: M. Iwan Fakhrudin, S.E., M.Tr. Opsla
K33: Letkol Laut (S) NRP 17789/P

Sheet PUSJIANSTRA
A5: LAPORAN SISA KAS
A6: SATKER PUSJIANSTRA TNI
A7: BULAN JULI 2025
A9: No | B9: Rekening | F9: Pencairan Dana | J9: Surat Persetujuan | L9: Tanggal Transaksi Terakhir | M9: Saldo Akhir Bank
B10: Nama | C10: Nomor | D10: Mata Uang | E10: Bank | F10: UP Tunai | G10: GUP | H10: LS Bendahara | I10: TUP | J10: Nomor | K10: Tanggal
A11: 1 | B11: 2 | C11: 3 | D11: 4 | E11: 5 | F11: 6 | G11: 7 | H11: 8 | I11: 9 | J11: 10 | K11: 11 | L11: 12 | M11: 13=6+7+8+9
A12: A | B12: Rekening Rutin
A13: 1 | B13: BPG 019 PUSJIANSTRA TNI | C13: 8.1001268e+15 | D13: Rupiah Murni | E13: Mandiri | F13: 0 | G13: 0 | H13: 43977500 | I13: 0 | J13: S-3034/WPB.12/KP.01/2020 | K13: 44140 | L13: 45847 | M13: 17540000
A15: B | B15: Rekening Pemerintah Lainnya (Hibah,BLU dan Lainnya)
A16: 1 | B16: RPL xxx PDH 684044 untuk xxxxxxxx (Nomor Reg Hibah)
A18: 2 | B18: RPL xxx KS Baranahan Kemhan untuk Kontrak DSME
A21: (3) | B21: (4) | C21: (5) | D21: (6) | E21: (7) | F21: (8) | G21: (9) | H21: (10) | I21: (11) | J21: (12) | K21: (13) | L21: (14) | M21: (15)
B24: JUMLAH (16) | M24: =SUM(M13:M20) -> 17540000
M25: USD
K27: Paku TNI Wilayah X
K32: M. Iwan Fakhrudin, S.E., M.Tr. Opsla
K33: Letkol Laut (S) NRP 17789/P

Sheet SETUM
A5: LAPORAN SISA KAS
A6: SATKER SETUM TNI
A7: BULAN JULI 2025
A9: No | B9: Rekening | F9: Pencairan Dana | J9: Surat Persetujuan | L9: Tanggal Transaksi Terakhir | M9: Saldo Akhir Bank
B10: Nama | C10: Nomor | D10: Mata Uang | E10: Bank | F10: UP Tunai | G10: GUP | H10: LS Bendahara | I10: TUP | J10: Nomor | K10: Tanggal
A11: 1 | B11: 2 | C11: 3 | D11: 4 | E11: 5 | F11: 6 | G11: 7 | H11: 8 | I11: 9 | J11: 10 | K11: 11 | L11: 12 | M11: 13=6+7+8+9
A12: A | B12: Rekening Rutin
A13: 1 | B13: BPG 088 SETUM TNI | C13: 8.1001268e+15 | D13: Rupiah Murni | E13: Mandiri | F13: 0 | G13: 0 | H13: 0 | I13: 0 | J13: S-3034/WPB.12/KP.01/2020 | K13: 44140 | L13: 45869
A15: B | B15: Rekening Pemerintah Lainnya (Hibah,BLU dan Lainnya)
A16: 1 | B16: RPL xxx PDH 684044 untuk xxxxxxxx (Nomor Reg Hibah)
A18: 2 | B18: RPL xxx KS Baranahan Kemhan untuk Kontrak DSME
A21: (3) | B21: (4) | C21: (5) | D21: (6) | E21: (7) | F21: (8) | G21: (9) | H21: (10) | I21: (11) | J21: (12) | K21: (13) | L21: (14) | M21: (15)
B24: JUMLAH (16) | M24: RP
M25: USD
K27: Paku TNI Wilayah XI
K32: Tono Prasatyo, S.E
K33: Mayor Cku NRP 11010020930476

Sheet BABINKUM
A5: LAPORAN SISA KAS
A6: SATKER BABINKUM TNI
A7: BULAN JULI 2025
A9: No | B9: Rekening | F9: Pencairan Dana | J9: Surat Persetujuan | L9: Tanggal Transaksi Terakhir | M9: Saldo Akhir Bank
B10: Nama | C10: Nomor | D10: Mata Uang | E10: Bank | F10: UP Tunai | G10: GUP | H10: LS Bendahara | I10: TUP | J10: Nomor | K10: Tanggal
A11: 1 | B11: 2 | C11: 3 | D11: 4 | E11: 5 | F11: 6 | G11: 7 | H11: 8 | I11: 9 | J11: 10 | K11: 11 | L11: 12 | M11: 13=6+7+8+9
A12: A | B12: Rekening Rutin
A13: 1 | B13: BPG 088 Babinkum TNI | C13: 8.1001268e+15 | D13: Rupiah Murni | E13: Mandiri | F13: 0 | G13: 0 | H13: 0 | I13: 0 | J13: S-1794/WPB.12/KP,01/2020 | K13: 44036 | L13: 45869 | M13: =F13+G13+H13+I13 -> 0
A15: B | B15: Rekening Pemerintah Lainnya (Hibah,BLU dan Lainnya)
A16: 1 | B16: RPL xxx PDH 684044 untuk xxxxxxxx (Nomor Reg Hibah)
A18: 2 | B18: RPL xxx KS Baranahan Kemhan untuk Kontrak DSME
A21: (3) | B21: (4) | C21: (5) | D21: (6) | E21: (7) | F21: (8) | G21: (9) | H21: (10) | I21: (11) | J21: (12) | K21: (13) | L21: (14) | M21: (15)
B24: JUMLAH (16) | M24: =SUM(M13:M19) -> 0
M25: USD
K27: Paku TNI Wilayah XI
K32: Tono Prasatyo, S.E
K33: Mayor Cku NRP 11010020930476

Sheet PUSBINTAL
A5: LAPORAN SISA KAS
A6: SATKER PUSBINTAL TNI
A7: BULAN JULI 2025
A9: No | B9: Rekening | F9: Pencairan Dana | J9: Surat Persetujuan | L9: Tanggal Transaksi Terakhir | M9: Saldo Akhir Bank
B10: Nama | C10: Nomor | D10: Mata Uang | E10: Bank | F10: UP Tunai | G10: GUP | H10: LS Bendahara | I10: TUP | J10: Nomor | K10: Tanggal
A11: 1 | B11: 2 | C11: 3 | D11: 4 | E11: 5 | F11: 6 | G11: 7 | H11: 8 | I11: 9 | J11: 10 | K11: 11 | L11: 12 | M11: 13=6+7+8+9
A12: A | B12: Rekening Rutin
A13: 1 | B13: BPG 088 PUSBINTAL TNI | C13: 8.1001268e+15 | D13: IDR | E13: MANDIRI | F13: 0 | G13: 0 | H13: 0 | I13: 0 | J13: S-3034/WPB.12/KP.01/2020 | K13: 44140 | L13: 45869 | M13: 0
A15: B | B15: Rekening Pemerintah Lainnya (Hibah,BLU dan Lainnya)
A16: 1 | B16: RPL xxx PDH 684044 untuk xxxxxxxx (Nomor Reg Hibah)
A18: 2 | B18: RPL xxx KS Baranahan Kemhan untuk Kontrak DSME
A21: (3) | B21: (4) | C21: (5) | D21: (6) | E21: (7) | F21: (8) | G21: (9) | H21: (10) | I21: (11) | J21: (12) | K21: (13) | L21: (14) | M21: (15)
B24: JUMLAH (16) | M24: =SUM(M12:M20) -> 0
M25: USD
K27: Paku TNI Wilayah XI
K32: Rono Prasetyo, S.E.
K33: Mayor Cku NRP 11010020930476

Sheet PUSKERSIN
A5: LAPORAN SISA KAS
A6: SATKER PUSKERSIN TNI
A7: BULAN JULI 2025
A9: No | B9: Rekening | F9: Pencairan Dana | J9: Surat Persetujuan | L9: Tanggal Transaksi Terakhir | M9: Saldo Akhir Bank
B10: Nama | C10: Nomor | D10: Mata Uang | E10: Bank | F10: UP Tunai | G10: GUP | H10: LS Bendahara | I10: TUP | J10: Nomor | K10: Tanggal
A11: 1 | B11: 2 | C11: 3 | D11: 4 | E11: 5 | F11: 6 | G11: 7 | H11: 8 | I11: 9 | J11: 10 | K11: 11 | L11: 12 | M11: 13=6+7+8+9
A12: A | B12: Rekening Rutin
A13: 1 | B13: BPG 686527 Puskersin TNI | C13: 8.1001269e+15 | D13: Rupiah Murni | E13: Mandiri | H13: 240128000 | J13: S-3034/WPB.12/KP.01/2020 | K13: 44140 | L13: 45863 | M13: 0
A15: B | B15: Rekening Pemerintah Lainnya (Hibah,BLU dan Lainnya)
A16: 1 | B16: RPL xxx PDH 684044 untuk xxxxxxxx (Nomor Reg Hibah)
A18: 2 | B18: RPL xxx KS Baranahan Kemhan untuk Kontrak DSME
A21: (3) | B21: (4) | C21: (5) | D21: (6) | E21: (7) | F21: (8) | G21: (9) | H21: (10) | I21: (11) | J21: (12) | K21: (13) | L21: (14) | M21: (15)
B24: JUMLAH (16) | M24: 0
M25: USD
K27: Paku TNI Wilayah XII
K32: Irwansyah, S.E.
K33: Letkol Laut (S) NRP 13526/P

Sheet PUSPOM
A5: LAPORAN SISA KAS
A6: SATKER PUSPOM TNI
A7: BULAN JULI 2025
A9: No | B9: Rekening | F9: Pencairan Dana | J9: Surat Persetujuan | L9: Tanggal Transaksi Terakhir | M9: Saldo Akhir Bank
B10: Nama | C10: Nomor | D10: Mata Uang | E10: Bank | F10: UP Tunai | G10: GUP | H10: LS Bendahara | I10: TUP | J10: Nomor | K10: Tanggal
A11: 1 | B11: 2 | C11: 3 | D11: 4 | E11: 5 | F11: 6 | G11: 7 | H11: 8 | I11: 9 | J11: 10 | K11: 11 | L11: 12 | M11: 13=6+7+8+9
A12: A | B12: Rekening Rutin
A13: 1 | B13: BPG 684182 Puspom TNI | C13: 8.1001268e+15 | D13: Rupiah Murni | E13: Mandiri | H13: 0 | J13: S-3034/WPB.12/KP.01/2020 | K13: 44140 | M13: 0
A15: B | B15: Rekening Pemerintah Lainnya (Hibah,BLU dan Lainnya)
A16: 1 | B16: RPL xxx PDH 684044 untuk xxxxxxxx (Nomor Reg Hibah)
A18: 2 | B18: RPL xxx KS Baranahan Kemhan untuk Kontrak DSME
A21: (3) | B21: (4) | C21: (5) | D21: (6) | E21: (7) | F21: (8) | G21: (9) | H21: (10) | I21: (11) | J21: (12) | K21: (13) | L21: (14) | M21: (15)
B24: JUMLAH (16) | M24: =SUM(M12:M20) -> 0
M25: USD
K27: Paku TNI Wilayah XII
K32: Irwansyah, S.E
K33: Letkol Laut (S) NRP 13526/P

Sheet PUSJAS
A5: LAPORAN SISA KAS
A6: SATKER PUSJAS TNI
A7: BULAN JULI 2025
A9: No | B9: Rekening | F9: Pencairan Dana | J9: Surat Persetujuan | L9: Tanggal Transaksi Terakhir | M9: Saldo Akhir Bank
B10: Nama | C10: Nomor | D10: Mata Uang | E10: Bank | F10: UP Tunai | G10: GUP | H10: LS Bendahara | I10: TUP | J10: Nomor | K10: Tanggal
A11: 1 | B11: 2 | C11: 3 | D11: 4 | E11: 5 | F11: 6 | G11: 7 | H11: 8 | I11: 9 | J11: 10 | K11: 11 | L11: 12 | M11: 13=6+7+8+9
A12: A | B12: Rekening Rutin
A13: 1 | B13: BPG 686521 PUSJASPERMILDAS TNI | C13: 8.1001269e+15 | D13: Rupiah Murni | E13: Mandiri | H13: 10850000 | J13: 000318 | K13: 44546 | L13: 45846 | M13: 0
A15: B | B15: Rekening Pemerintah Lainnya (Hibah,BLU dan Lainnya)
A16: 1 | B16: RPL xxx PDH 684044 untuk xxxxxxxx (Nomor Reg Hibah)
A18: 2 | B18: RPL xxx KS Baranahan Kemhan untuk Kontrak DSME
A21: (3) | B21: (4) | C21: (5) | D21: (6) | E21: (7) | F21: (8) | G21: (9) | H21: (10) | I21: (11) | J21: (12) | K21: (13) | L21: (14) | M21: (15)
B24: JUMLAH (16) | M24: =SUM(M12:M20) -> 0
M25: USD
K27: Paku TNI Wilayah XII
K32: Irwansyah, S.E
K33: Letkol Laut (S) NRP 1352/P

Sheet SATSIBER
A5: LAPORAN SISA KAS
A6: SATKER SATSIBER TNI
A7: BULAN JULI 2025
A9: No | B9: Rekening | F9: Pencairan Dana | J9: Surat Persetujuan | L9: Tanggal Transaksi Terakhir | M9: Saldo Akhir Bank
B10: Nama | C10: Nomor | D10: Mata Uang | E10: Bank | F10: UP Tunai | G10: GUP | H10: LS Bendahara | I10: TUP | J10: Nomor | K10: Tanggal
A11: 1 | B11: 2 | C11: 3 | D11: 4 | E11: 5 | F11: 6 | G11: 7 | H11: 8 | I11: 9 | J11: 10 | K11: 11 | L11: 12 | M11: 13=6+7+8+9
A12: A | B12: Rekening Rutin
A13: 1 | B13: BPG 417650 Satsiber TNI | C13: 8.1001242e+15 | D13: Rupiah Murni | E13: Mandiri | H13: 72362825 | J13: S-3034/WPB.12/KP.01/2020 | K13: 44140 | L13: 45866 | M13: 0
A15: B | B15: Rekening Pemerintah Lainnya (Hibah,BLU dan Lainnya)
A16: 1 | B16: RPL xxx PDH 684044 untuk xxxxxxxx (Nomor Reg Hibah)
A18: 2 | B18: RPL xxx KS Baranahan Kemhan untuk Kontrak DSME
A21: (3) | B21: (4) | C21: (5) | D21: (6) | E21: (7) | F21: (8) | G21: (9) | H21: (10) | I21: (11) | J21: (12) | K21: (13) | L21: (14) | M21: (15)
B24: JUMLAH (16) | M24: =SUM(M12:M19) -> 0
M25: USD
K27: Paku TNI Wilayah XII
K32: Irwansyah, S.E
K33: Letkol Laut (S) NRP 13526/P

Sheet GARTAP I
A5: LAPORAN SISA KAS
A6: SATKER KOGARTAP I/JKT
A7: BULAN JULI 2025
A9: No | B9: Rekening | F9: Pencairan Dana | J9: Surat Persetujuan | L9: Tanggal Transaksi Terakhir | M9: Saldo Akhir Bank
B10: Nama | C10: Nomor | D10: Mata Uang | E10: Bank | F10: UP Tunai | G10: GUP | H10: LS Bendahara | I10: TUP | J10: Nomor | K10: Tanggal
A11: 1 | B11: 2 | C11: 3 | D11: 4 | E11: 5 | F11: 6 | G11: 7 | H11: 8 | I11: 9 | J11: 10 | K11: 11 | L11: 12 | M11: 13=6+7+8+9
A12: A | B12: Rekening Rutin
A13: 1 | B13: BPG 019 KOGARTAP I JKT | C13: 8.1001268e+15 | D13: IDR | E13: MANDIRI | G13: 300000000 | I13: 956997800 | J13: S-3034/WPB.12/KP.01/2020 | K13: 44140 | L13: 45847 | M13: 0
A15: B | B15: Rekening Pemerintah Lainnya (Hibah,BLU dan Lainnya)
A16: 1 | B16: RPL xxx PDH 684044 untuk xxxxxxxx (Nomor Reg Hibah)
A18: 2 | B18: RPL xxx KS Baranahan Kemhan untuk Kontrak DSME
A21: (3) | B21: (4) | C21: (5) | D21: (6) | E21: (7) | F21: (8) | G21: (9) | H21: (10) | I21: (11) | J21: (12) | K21: (13) | L21: (14) | M21: (15)
B24: JUMLAH (16) | M24: RP
M25: USD
K27: Paku TNI Wilayah XIII
K32: Iwan Setiawan, S.E.
K33: Mayor Cku NRP 11030005171076

Sheet PUSINFORMAR
A5: LAPORAN SISA KAS
A6: SATKER PUSINFORMAR
A7: BULAN JULI 2025
A9: No | B9: Rekening | F9: Pencairan Dana | J9: Surat Persetujuan | L9: Tanggal Transaksi Terakhir | M9: Saldo Akhir Bank
B10: Nama | C10: Nomor | D10: Mata Uang | E10: Bank | F10: UP Tunai | G10: GUP | H10: LS Bendahara | I10: TUP | J10: Nomor | K10: Tanggal
A11: 1 | B11: 2 | C11: 3 | D11: 4 | E11: 5 | F11: 6 | G11: 7 | H11: 8 | I11: 9 | J11: 10 | K11: 11 | L11: 12 | M11: 13=6+7+8+9
A12: A | B12: Rekening Rutin
A13: 1 | B13: BPG 018 PUSINFORMAR TNI | C13: 8.1001264e+15 | D13: IDR | E13: Mandiri | F13: 0 | G13: 0 | H13: 75082500 | I13: 0 | J13: S-522/WPB.12/KP.01/2021 | K13: 44249 | L13: 45842 | M13: 0
A15: B | B15: Rekening Pemerintah Lainnya (Hibah,BLU dan Lainnya)
A16: 1 | B16: RPL xxx PDH 684044 untuk xxxxxxxx (Nomor Reg Hibah)
A18: 2 | B18: RPL xxx KS Baranahan Kemhan untuk Kontrak DSME
A21: (3) | B21: (4) | C21: (5) | D21: (6) | E21: (7) | F21: (8) | G21: (9) | H21: (10) | I21: (11) | J21: (12) | K21: (13) | L21: (14) | M21: (15)
B24: JUMLAH (16) | M24: =SUM(M13:M20) -> 0
M25: USD
K27: Paku TNI Wilayah XIII
K32: Iwan Setiawan, S.E.
K33: Mayor Cku NRP 11030005171076

Sheet KOGABWILHAN III
A5: LAPORAN SISA KAS
A6: SATKER KOGABWILHAN III
A7: BULAN JULI 2025
A9: No | B9: Rekening | F9: Pencairan Dana | J9: Surat Persetujuan | L9: Tanggal Transaksi Terakhir | M9: Saldo Akhir Bank
B10: Nama | C10: Nomor | D10: Mata Uang | E10: Bank | F10: UP Tunai | G10: GUP | H10: LS Bendahara | I10: TUP | J10: Nomor | K10: Tanggal
A11: 1 | B11: 2 | C11: 3 | D11: 4 | E11: 5 | F11: 6 | G11: 7 | H11: 8 | I11: 9 | J11: 10 | K11: 11 | L11: 12 | M11: 13=6+7+8+9
A12: A | B12: Rekening Rutin
A13: 1 | B13: BPG 141 KOGABWILHAN III | C13: 8.1001263e+15 | D13: Rupiah Murni | E13: Mandiri | F13: 0 | G13: 0 | H13: 0 | I13: 0 | L13: 45862 | M13: 0
A15: B | B15: Rekening Pemerintah Lainnya (Hibah,BLU dan Lainnya)
A16: 1 | B16: RPL xxx PDH 684044 untuk xxxxxxxx (Nomor Reg Hibah)
A18: 2 | B18: RPL xxx KS Baranahan Kemhan untuk Kontrak DSME
A21: (3) | B21: (4) | C21: (5) | D21: (6) | E21: (7) | F21: (8) | G21: (9) | H21: (10) | I21: (11) | J21: (12) | K21: (13) | L21: (14) | M21: (15)
B24: JUMLAH (16) | M24: =SUM(M13:M20) -> 0
M25: USD
K27: Kaku TNI Wilayah Papua III
K32: Eko Sugiarto, S.E., M.Si., C.Fr.A
K33: Kolonel Laut (S) NRP 12929/P

Sheet REKAP LAPSIKAS
A5: LAPORAN SISA KAS
A6: SATKER LAYANAN KUPUS II
A7: BULAN JULI 2025
A9: No | B9: Rekening | F9: Pencairan Dana | J9: Surat Persetujuan | L9: Tanggal Transaksi Terakhir | M9: Saldo Akhir Bank
B10: Nama | C10: Nomor | D10: Mata Uang | E10: Bank | F10: UP Tunai | G10: GUP | H10: LS Bendahara | I10: TUP | J10: Nomor | K10: Tanggal
A11: 1 | B11: 2 | C11: 3 | D11: 4 | E11: 5 | F11: 6 | G11: 7 | H11: 8 | I11: 9 | J11: 10 | K11: 11 | L11: 12 | M11: 13=6+7+8+9
A12: A | B12: Rekening Rutin
B13: PAKU VI
B14: Babek TNI | C14: =BABEK!C$13 -> 8.1001268e+15 | D14: =BABEK!D$13 -> Rupiah Murni | E14: =BABEK!E$13 -> Mandiri | F14: =BABEK!F$13 -> 0 | G14: =BABEK!G$13 -> 0 | H14: =BABEK!H$13 -> 81368200 | I14: =BABEK!I$13 -> 0 | J14: =BABEK!J$13 -> 000311 | ... L14: =BABEK!L$13 -> 45869 | M14: =F14+G14+H14+I15 -> 81368200
B16: PAKU VII
B17: Puskes TNI | C17: =PUSKES!C$13 -> 8.1001268e+15 | D17: =PUSKES!D13 -> Rupiah Murni | E17: =PUSKES!E13 -> Mandiri | F17: =PUSKES!F13 -> 0 | G17: =PUSKES!G13 -> 0 | H17: =PUSKES!H13 -> 42498039 | I17: =PUSKES!I13 -> 0 | J17: =PUSKES!J13 -> 000313 | K17: =PUSKES!K13 -> 44546 | L17: =PUSKES!L13 -> 45867 | M17: =F17+G17+H17+I18 -> 42498039
B18: Puspsi | C18: =PUSPSI!C$13 -> 8.1001234e+15 | D18: =PUSPSI!D$13 -> Rupiah Murni | E18: =PUSPSI!E$13 -> Mandiri | F18: =PUSPSI!F$13 -> 0 | G18: =PUSPSI!G$13 -> 0 | H18: =PUSPSI!H$13 -> 0 | I18: =PUSPSI!I$13 -> 0 | J18: =PUSPSI!J$13 -> S-3573/KPN.1201/2022 | ... L18: =PUSPSI!L$13 -> 45869 | M18: =F18+G18+H18+I19 -> 0
B20: PAKU VIII
B21: Bais TNI | C21: =BAIS!C$13 -> 8.1001268e+15 | D21: =BAIS!D$13 -> IDR | E21: =BAIS!E$13 -> MANDIRI | F21: =BAIS!F$13 -> 40000000000 | G21: =BAIS!G$13 -> 61838666657 | H21: =BAIS!H$13 -> 21483352530 | I21: =BAIS!I$13 -> 0 | J21: =BAIS!J$13 -> S-3034/WPB.12/KP.01/2020 | ... L21: =BAIS!L$13 -> 45861 | M21: =F21+G21+H21+I22 -> 123322019187
B23: PAKU IX
B24: Pusku TNI | C24: =PUSKU!C$13 -> 8.1001268e+15 | D24: =PUSKU!D$13 -> IDR | E24: =PUSKU!E$13 -> Mandiri | F24: =PUSKU!F$13 -> 0 | G24: =PUSKU!G$13 -> 0 | H24: =PUSKU!H$13 -> 402818432 | I24: =PUSKU!I$13 -> 0 | J24: =PUSKU!J$13 -> S-3034/WPB.12/KP.01/2020 | ... L24: =PUSKU!L$13 -> - | M24: =F24+G24+H24+I25 -> 402818432
B25: Mako Akademi TNI | C25: ='MAKO AKADEMI'!C$13 -> 8.1001268e+15 | D25: ='MAKO AKADEMI'!D$13 -> IDR | E25: ='MAKO AKADEMI'!E$13 -> Mandiri | F25: ='MAKO AKADEMI'!F$13 -> 0 | G25: ='MAKO AKADEMI'!G$13 -> 0 | H25: ='MAKO AKADEMI'!H$13 -> 387181048 | I25: ='MAKO AKADEMI'!I$13 -> 0 | J25: ='MAKO AKADEMI'!J$13 -> S-3034/WPB.12/KP.01/2020 | ... L25: ='MAKO AKADEMI'!L$13 -> 45862 | M25: =F25+G25+H25+I26 -> 387181048
B26: Puspen TNI | C26: =PUSPEN!C$13 -> 8.1001268e+15 | D26: =PUSPEN!D$13 -> IDR | E26: =PUSPEN!E$13 -> Mandiri | F26: =PUSPEN!F$13 -> 0 | G26: =PUSPEN!G$13 -> 0 | H26: =PUSPEN!H$13 -> 38670000 | I26: =PUSPEN!I$13 -> 0 | J26: =PUSPEN!J$13 -> S-3034/WPB,12/KP,01/2020 | ... L26: =PUSPEN!L$13 -> 45868 | M26: =F26+G26+H26+I27 -> 38670000
B27: Pusdalops TNI | C27: =PUSDALOPS!C$13 -> 8.1001268e+15 | D27: =PUSDALOPS!D$13 -> IDR | E27: =PUSDALOPS!E$13 -> Mandiri | F27: =PUSDALOPS!F$13 -> 0 | G27: =PUSDALOPS!G$13 -> 0 | H27: =PUSDALOPS!H$13 -> 52478500 | I27: =PUSDALOPS!I$13 -> 0 | J27: =PUSDALOPS!J$13 -> S-3034/wpb,12/kp.01/2020 | ... L27: =PUSDALOPS!L$13 -> 45866 | M27: =F27+G27+H27+I28 -> 52478500
B29: PAKU X
B30: Paspampres | C30: =PASPAMPRES!C$13 -> 8.1001268e+15 | D30: =PASPAMPRES!D$13 -> Rupiah Murni | E30: =PASPAMPRES!E$13 -> Mandiri | F30: =PASPAMPRES!F$13 -> 0 | G30: =PASPAMPRES!G$13 -> 0 | H30: =PASPAMPRES!H$13 -> 135556104 | I30: =PASPAMPRES!I$13 -> 0 | J30: =PASPAMPRES!J$13 -> S-3034/WPB.12/KP.01/2020 | ... L30: =PASPAMPRES!L$13 -> 45867 | M30: =F30+G30+H30+I31 -> 135556104
B31: Pusjianstra TNI | C31: =PUSJIANSTRA!C$13 -> 8.1001268e+15 | D31: =PUSJIANSTRA!D$13 -> Rupiah Murni | E31: =PUSJIANSTRA!E$13 -> Mandiri | F31: =PUSJIANSTRA!F$13 -> 0 | G31: =PUSJIANSTRA!G$13 -> 0 | H31: =PUSJIANSTRA!H$13 -> 43977500 | I31: =PUSJIANSTRA!I$13 -> 0 | J31: =PUSJIANSTRA!J$13 -> S-3034/WPB.12/KP.01/2020 | ... L31: =PUSJIANSTRA!L$13 -> 45847 | M31: =F31+G31+H31+I32 -> 43977500
B33: PAKU XI
B34: Babinkum TNI | C34: =BABINKUM!C$13 -> 8.1001268e+15 | D34: =BABINKUM!D$13 -> Rupiah Murni | E34: =BABINKUM!E$13 -> Mandiri | F34: =BABINKUM!F$13 -> 0 | G34: =BABINKUM!G$13 -> 0 | H34: =BABINKUM!H$13 -> 0 | I34: =BABINKUM!I$13 -> 0 | J34: =BABINKUM!J$13 -> S-1794/WPB.12/KP,01/2020 | ... L34: =BABINKUM!L$13 -> 45869 | M34: =F34+G34+H34+I35 -> 0
B35: Setum TNI | C35: =SETUM!C$13 -> 8.1001268e+15 | D35: =SETUM!D$13 -> Rupiah Murni | E35: =SETUM!E$13 -> Mandiri | F35: =SETUM!F$13 -> 0 | G35: =SETUM!G$13 -> 0 | H35: =SETUM!H$13 -> 0 | I35: =SETUM!I$13 -> 0 | J35: =SETUM!J$13 -> S-3034/WPB.12/KP.01/2020 | ... L35: =SETUM!L$13 -> 45869 | M35: =F35+G35+H35+I36 -> 0
B36: Pusbintal TNI | C36: =PUSBINTAL!C$13 -> 8.1001268e+15 | D36: =PUSBINTAL!D$13 -> IDR | E36: =PUSBINTAL!E$13 -> MANDIRI | F36: =PUSBINTAL!F$13 -> 0 | G36: =PUSBINTAL!G$13 -> 0 | H36: =PUSBINTAL!H$13 -> 0 | I36: =PUSBINTAL!I$13 -> 0 | J36: =PUSBINTAL!J$13 -> S-3034/WPB.12/KP.01/2020 | ... L36: =PUSBINTAL!L$13 -> 45869 | M36: =F36+G36+H36+I37 -> 0
M37: =F37+G37+H37+I38 -> 0
B38: PAKU XII | M38: =F38+G38+H38+I39 -> 0
B39: Pusjaspermildas TNI | C39: =PUSJAS!C$13 -> 8.1001269e+15 | D39: =PUSJAS!D$13 -> Rupiah Murni | E39: =PUSJAS!E$13 -> Mandiri | F39: =PUSJAS!F$13 -> 0 | G39: =PUSJAS!G$13 -> 0 | H39: =PUSJAS!H$13 -> 10850000 | I39: =PUSJAS!I$13 -> 0 | J39: =PUSJAS!J$13 -> 000318 | ... L39: =PUSJAS!L$13 -> 45846 | M39: =F39+G39+H39+I40 -> 10850000
B40: Puskersin TNI | C40: =PUSKERSIN!C$13 -> 8.1001269e+15 | D40: =PUSKERSIN!D$13 -> Rupiah Murni | E40: =PUSKERSIN!E$13 -> Mandiri | F40: =PUSKERSIN!F$13 -> 0 | G40: =PUSKERSIN!G$13 -> 0 | H40: =PUSKERSIN!H$13 -> 240128000 | I40: =PUSKERSIN!I$13 -> 0 | J40: =PUSKERSIN!J$13 -> S-3034/WPB.12/KP.01/2020 | ... L40: =PUSKERSIN!L$13 -> 45863 | M40: =F40+G40+H40+I41 -> 240128000
B41: Pom TNI | C41: =PUSPOM!C$13 -> 8.1001268e+15 | D41: =PUSPOM!D$13 -> Rupiah Murni | E41: =PUSPOM!E$13 -> Mandiri | F41: =PUSPOM!F$13 -> 0 | G41: =PUSPOM!G$13 -> 0 | H41: =PUSPOM!H$13 -> 0 | I41: =PUSPOM!I$13 -> 0 | J41: =PUSPOM!J$13 -> S-3034/WPB.12/KP.01/2020 | ... L41: =PUSPOM!L$13 -> 0 | M41: =F41+G41+H41+I42 -> 0
B42: Satsiber TNI | C42: =SATSIBER!C$13 -> 8.1001242e+15 | D42: =SATSIBER!D$13 -> Rupiah Murni | E42: =SATSIBER!E$13 -> Mandiri | F42: =SATSIBER!F$13 -> 0 | G42: =SATSIBER!G$13 -> 0 | H42: =SATSIBER!H$13 -> 72362825 | I42: =SATSIBER!I$13 -> 0 | J42: =SATSIBER!J$13 -> S-3034/WPB.12/KP.01/2020 | ... L42: =SATSIBER!L$13 -> 45866 | M42: =F42+G42+H42+I43 -> 72362825
M43: =F43+G43+H43+I44 -> 0
B44: PAKU XIII | M44: =F44+G44+H44+I45 -> 0
B45: Pusinfomar | C45: =PUSINFORMAR!C$13 -> 8.1001264e+15 | D45: =PUSINFORMAR!D$13 -> IDR | E45: =PUSINFORMAR!E$13 -> Mandiri | F45: =PUSINFORMAR!F$13 -> 0 | G45: =PUSINFORMAR!G$13 -> 0 | H45: =PUSINFORMAR!H$13 -> 75082500 | I45: =PUSINFORMAR!I$13 -> 0 | J45: =PUSINFORMAR!J$13 -> S-522/WPB.12/KP.01/2021 | ... L45: =PUSINFORMAR!L$13 -> 45842 | M45: =F45+G45+H45+I45 -> 75082500
B46: Kogartap I/Jkt | C46: ='GARTAP I'!C$13 -> 8.1001268e+15 | D46: ='GARTAP I'!D$13 -> IDR | E46: ='GARTAP I'!E$13 -> MANDIRI | F46: ='GARTAP I'!F$13 -> 0 | G46: ='GARTAP I'!G$13 -> 300000000 | H46: ='GARTAP I'!H$13 -> 0 | I46: ='GARTAP I'!I$13 -> 956997800 | J46: ='GARTAP I'!J$13 -> S-3034/WPB.12/KP.01/2020 | ... L46: ='GARTAP I'!L$13 -> 45847 | M46: =F46+G46+H46+I46 -> 1256997800
B48: PAPUA III
B49: Kogabwilhan III | C49: ='KOGABWILHAN III'!C$13 -> 8.1001263e+15 | D49: ='KOGABWILHAN III'!D$13 -> Rupiah Murni | E49: ='KOGABWILHAN III'!E$13 -> Mandiri | F49: ='KOGABWILHAN III'!F$13 -> 0 | G49: ='KOGABWILHAN III'!G$13 -> 0 | H49: ='KOGABWILHAN III'!H$13 -> 0 | I49: ='KOGABWILHAN III'!I$13 -> 0 | J49: ='KOGABWILHAN III'!J$13 -> 0 | ... L49: ='KOGABWILHAN III'!L$13 -> 45862 | M49: =F49+G49+H49+I50 -> 0
A52: B | B52: Rekening Pemerintah Lainnya (Hibah,BLU dan Lainnya)
A53: 1 | B53: RPL xxx PDH 684044 untuk xxxxxxxx (Nomor Reg Hibah)
...

Sheet WILAYAH
A6: LAPORAN SISA KAS
A7: KOTAMA/WILAYAH ………………….. (1)
A8: BULAN …….…………….. (2)
A10: No | B10: Uraian | D10: Rekening | H10: Pencairan Dana | L10: Surat Persetujuan | N10: Tanggal Transaksi Terakhir | O10: Saldo Akhir Bank | P10: Nama Kontrak Tgl. Berakhir | Q10: Nilai | R10: SP2D-Sisa
B11: Kode | C11: Nama | D11: Nama | E11: Nomor | F11: Mata Uang | G11: Bank | H11: UP Tunai | I11: GUP | J11: LS Bendahara | K11: TUP | L11: Nomor | M11: Tanggal
A12: 1 | B12: 2 | C12: 3 | D12: 4 | E12: 5 | F12: 6 | G12: 7 | H12: 8 | I12: 9 | J12: 10 | K12: 11 | L12: 12 | M12: 13 | N12: 14 | O12: 15=8+9+10+11 | P12: 14 | Q12: 15 | R12: 16
A13: A | B13: Rekening Rutin
A14: 1 | B14: xxxxxx | C14: Paldam-I/BB
A16: 2 | B16: xxxxxx | C16: Zidam-I/BB
A17: dst
A20: B | B20: Rekening Pemerintah Lainnya (Hibah,BLU dan Lainnya)
A21: 1 | B21: xxxxxx | C21: Paldam-I/BB
A23: 2 | B23: xxxxxx | C23: Zidam-I/BB
A24: dst
A26: (3) | B26: (4) | C26: (5) | D26: (6) | E26: (7) | F26: (8) | G26: (9) | H26: (10) | I26: (11) | J26: (12) | K26: (13) | L26: (14) | M26: (15) | N26: (16) | O26: (17) | P26: (14)
C28: JUMLAH (18) | O28: Rp
O29: USD
L31: Kaku Kotama/Kaku Wilayah
P32: KPA/PPSPM/Kepala Satuan Kerja
L36: Nama
L37: Pangkat/ NRP/NIP
P38: Nama
P39: Pangkat NRP/NIP

Sheet UO
B6: LAPORAN SISA KAS
B7: UO …………..…...(1)
B8: BULAN…………….. (2)
B10: No | C10: Uraian | E10: Rekening | I10: Pencairan Dana | M10: Surat Persetujuan | O10: Tanggal Transaksi Terakhir | P10: Saldo Akhir Bank
C11: Kode | D11: Nama | E11: Nama | F11: Nomor | G11: Mata Uang | H11: Bank | I11: UP Tunai | J11: GUP | K11: LS Bendahara | L11: TUP | M11: Nomor | N11: Tanggal
B12: 1 | C12: 2 | D12: 3 | E12: 4 | F12: 5 | G12: 6 | H12: 7 | I12: 8 | J12: 9 | K12: 10 | L12: 11 | M12: 12 | N12: 13 | O12: 14 | P12: 15=8+9+10+11
B13: A | C13: Rekening Rutin
B14: 1 | C14: Kudam I/BB
B15: a | C15: xxxxxx | D15: Paldam-I/BB
B16: b | C16: xxxxxx | D16: Zidam-I/BB
B18: 2 | C18: Kudam II Swj
B19: a | C19: xxxxxx | D19: Rindam-II/SWJ
B20: b | C20: xxxxxx | D20: Paldam-II/SWJ
B21: dst
B23: B | C23: Rekening Pemerintah Lainnya (Hibah,BLU dan Lainnya)
B24: 1 | C24: Kudam I/BB
B25: a | C25: xxxxxx | D25: Paldam-I/BB
B26: b | C26: xxxxxx | D26: Zidam-I/BB
B28: 2 | C28: Kudam II/Swj
B29: a | C29: xxxxxx | D29: Rindam-II/SWJ
B30: b | C30: xxxxxx | D30: Paldam-II/SWJ
B31: dst
B33: (3) | C33: (4) | D33: (5) | E33: (6) | F33: (7) | G33: (8) | H33: (9) | I33: (10) | J33: (11) | K33: (12) | L33: (13) | M33: (14) | N33: (15) | O33: (16) | P33: (17)
C35: JUMLAH (18) | P35: Rp
P36: USD
M39: Kapusku TNI/ Dirku/Kadisku Angkatan,
M44: Nama
M45: Pangkat NRP/NIP
B86: LAPORAN SISA KAS
B87: UO KEMHAN
B88: BULAN………………..
B90: No | C90: Satker | E90: REKENING | I90: Peruntukan | P90: Saldo Akhir Bank (8+9+10)
C91: Kode | D91: Nama | E91: Nama | F91: Nomor | G91: Mata Uang | H91: Bank | I91: UP | K91: LS Bendahara | L91: TUP
C92: 2 | D92: 3 | E92: 4 | F92: 5 | G92: 6 | H92: 7 | I92: 8 | K92: 9 | L92: 10 | P92: 14 | Q92: 12 | R92: 13
B93: A | C93: Rekening Rutin
B94: 1 | C94: xxxxxx | D94: Baranahan Kemhan
B95: 2 | C95: xxxxxx | D95: Ditjen Strahan Kemhan
B96: 3 | C96: xxxxxx | D96: Puslapbinkuhan Kemhan
B97: dst
B98: B | C98: Rekening Pemerintah Lainnya (Hibah,BLU dan Lainnya)
...

Sheet KEMHAN DAN TNI
A5: LAPORAN SISA KAS
A6: KEMHAN DAN TNI
A7: BULAN…………….. (1)
A9: No | B9: Uraian | D9: Rekening | H9: Pencairan Dana | L9: Surat Persetujuan | N9: Tanggal Transaksi Terakhir | O9: Saldo Akhir Bank
B10: Kode | C10: Nama | D10: Nama | E10: Nomor | F10: Mata Uang | G10: Bank | H10: UP Tunai | I10: GUP | J10: LS Bendahara | K10: TUP | L10: Nomor | M10: Persetujuan
A11: 1 | B11: 2 | C11: 3 | D11: 4 | E11: 5 | F11: 6 | G11: 7 | H11: 8 | I11: 9 | J11: 10 | K11: 11 | L11: 12 | M11: 13 | N11: 14 | O11: 15=8+9+10+11
A12: A | B12: Rekening Rutin
A14: 1 | B14: UO KEMHAN
A15: a | B15: xxxxxxx | C15: Baranahan
A16: b | B16: xxxxxxx | C16: Puslapbinkuhan
A18: 2 | B18: UO MABES TNI
A19: a | B19: xxxxxxx | C19: Puspen TNI
A20: b | B20: xxxxxxx | C20: BAIS TNI
A22: 3 | B22: UO TNI AD
A23: a | B23: Kudam I/BB
A24: 1) | B24: xxxxxx | C24: Paldam I/BB
A25: 2) | B25: xxxxxx | C25: Zidam I/BB
A26: b | B26: Kudam II/SWJ
A27: 1) | B27: xxxxxx | C27: Paldam II/SWJ
A28: 2) | B28: xxxxxx | C28: Zidam II/SWJ
A30: 4 | B30: UO TNI AL
A31: a | B31: Koarmada II
A32: 1) | B32: xxxxxx | C32: Satkor Koarmada II
A33: 2) | B33: xxxxxx | C33: Satfib Koarmada II
A34: b | B34: Kormar
A35: 1) | B35: xxxxxx | C35: Lanmar Jakarta
A36: 2) | B36: xxxxxx | C36: Pasmar I
A38: 5 | B38: UO TNI AU
A39: a | B39: Kotama Koopsau I
A40: 1) | B40: xxxxxx | C40: Lanud Sultan Iskandar Muda
A41: 2) | B41: xxxxxx | C41: Lanud Maimun Saleh
A42: B | B42: Rekening Pemerintah Lainnya (Hibah,BLU dan Lainya)
A44: 1 | B44: UO KEMHAN
A45: a | B45: xxxxxxx | C45: Baranahan
A46: b | B46: xxxxxxx | C46: Puslapbinkuhan
A48: 2 | B48: UO MABES TNI
A49: a | B49: xxxxxxx | C49: Puspen TNI
A50: b | B50: xxxxxxx | C50: BAIS TNI
A53: 2
A56: No | B56: Uraian | D56: Rekening | H56: Pencairan Dana | L56: Surat Persetujuan | N56: Tanggal Transaksi Terakhir | O56: Saldo Akhir Bank
...

Sheet CONTOH
A2: LAPORAN SISA KAS
A3: SATKER ……………………… (1)
A4: BULAN ……..…………….. (2)
A6: No | B6: Rekening | G6: Peruntukan | J6: Surat Persetujuan | L6: Tanggal Transaksi terakhir | M6: Saldo Akhir Bank (5+6+7) | N6: Nama Kontrak Tgl. Berakhir | O6: Nilai | P6: SP2D-Sisa
B7: Nama | C7: Nomor | D7: Nama | E7: Mata Uang | F7: Bank | G7: UP Tunai | H7: LS Bendahara | I7: TUP | J7: Nomor | K7: Tanggal
A8: 1 | B8: 2 | C8: 3 | D8: 5 | E8: 4 | F8: 5 | G8: 6 | H8: 7 | I8: 8 | J8: 9 | K8: 10 | L8: 11 | M8: 12 | N8: 14 | O8: 15 | P8: 16
A9: A | B9: Rekening Rutin
A10: 1 | B10: BPG 019 Puslapbinkuhan | C10: 1230000000 | E10: IDR | F10: Bank xxx | G10: xxx.xxx | H10: xxx.xxxx | I10: xxx.xxx | J10: S/ /xx/20xx | K10: xx-xx-xxxx | M10: xxx.xxx
A13: B | B13: Rekening Pemerintah Lainnya (Hibah,BLU dan Lainya)
A14: 1 | B14: RPL019 PDH 684044 untuk zxxxxxx (Nomor Reg Hibah) | C14: 1230000000 | E14: IDR | F14: Bank xxx | G14: - | H14: - | I14: - | J14: S/ /xx/20xx | K14: xx-xx-xxxx | M14: xxx.xxx
A16: 2 | B16: RPL019 KS Baranahan Kemhan untuk Kontrak DSME | C16: 1230000000 | E16: USD | F16: Bank xxx | G16: - | H16: - | I16: - | J16: S/ /xx/20xx | K16: xx-xx-xxxx | M16: xxx.xxx
A19: (3) | B19: (4) | C19: (5) | D19: (7) | E19: (6) | F19: (7) | G19: (8) | H19: (9) | I19: (10) | J19: (11) | K19: (12) | L19: (13) | M19: (14) | N19: (14)
B22: JUMLAH (15)
N24: KPA/PPSPM/Kepala Satuan Kerja
K26: Kepala Satuan Kerja
N30: Nama
N31: Pangkat NRP/NIP
K32: Nama
K33: Pangkat NRP/NIP

Sheet wilayah (2)
A2: LAPORAN SISA KAS
A3: KOTAMA/WILAYAH ………………….. (1)
A4: BULAN …….…………….. (2)
A6: No | B6: URAIAN | D6: Rekening | H6: Peruntukan | L6: Surat Persetujuan | N6: Tanggal Transaksi Terakhir | O6: Saldo Akhir Bank (8+9+10) | P6: Nama Kontrak Tgl. Berakhir | Q6: Nilai | R6: SP2D-Sisa
B7: Kode | C7: Nama | D7: Nama | E7: Nomor | F7: Mata Uang | G7: Bank | H7: UP | I7: GUP | J7: LS Bendahara | K7: TUP | L7: Nomor | M7: Tanggal
A8: 1 | B8: 2 | C8: 3 | D8: 4 | E8: 5 | F8: 6 | G8: 7 | H8: 8 | I8: 9 | J8: 10 | K8: 11 | L8: 12 | M8: 13 | N8: 14 | O8: 15 | P8: 14 | Q8: 15 | R8: 16
A9: A | B9: Rekening Rutin
A10: 1 | B10: xxxxxx | C10: Paldam-I/BB | D10: BPG xxx Paldam | E10: 1230000000 | F10: IDR | G10: Bank xxx | H10: xxx.xxx | I10: xxx.xxx | J10: xxx.xxx | K10: xxx.xxx | L10: S/ /xx/20xx | M10: dd-mm-yyyy | N10: dd-mm-yyyy | O10: xxx.xxx
A12: 2 | B12: xxxxxx | C12: Zidam-I/BB | D12: BPG xxx Zidam | E12: 1230000000 | F12: IDR | G12: Bank xxx | H12: xxx.xxx | I12: xxx.xxx | J12: xxx.xxx | K12: xxx.xxx | L12: S/ /xx/20xx | M12: dd-mm-yyyy | N12: dd-mm-yyyy | O12: xxx.xxx
A13: dst
A16: B | B16: Rekening Pemerintah Lainnya (Hibah,BLU dan Lainnya)
A17: 1 | B17: xxxxxx | C17: Paldam-I/BB | D17: RPL xxx PDH untuk 1234567 | E17: 1230000000 | F17: IDR | G17: Bank xxx | H17: - | I17: - | J17: - | K17: - | L17: S/ /xx/20xx | M17: dd-mm-yyyy | N17: dd-mm-yyyy | O17: xxx.xxx
A19: 2 | B19: xxxxxx | C19: Zidam-I/BB | D19: RPL xxx PDH untuk 1234567 | E19: 1230000000 | F19: IDR | G19: Bank xxx | H19: - | I19: - | J19: - | K19: - | L19: S/ /xx/20xx | M19: dd-mm-yyyy | N19: dd-mm-yyyy | O19: xxx.xxx
A20: dst
A22: (3) | B22: (4) | C22: (5) | D22: (6) | E22: (7) | F22: (8) | G22: (9) | H22: (10) | I22: (11) | J22: (12) | K22: (13) | L22: (14) | M22: (15) | N22: (16) | O22: (17) | P22: (14)
C24: JUMLAH (18)
P27: KPA/PPSPM/Kepala Satuan Kerja
L28: Kaku kotama/Kaku Wilayah
L33: Nama | P33: Nama
L34: Pangkat NRP/NIP | P34: Pangkat NRP/NIP

Sheet UO (2)
A2: LAPORAN SISA KAS
A3: UO …………..…...(1)
A4: BULAN…………….. (2)
A6: No | B6: URAIAN | D6: Rekening | H6: Peruntukan | L6: Surat Persetujuan | N6: Tanggal Transaksi Terakhir | O6: Saldo Akhir Bank (8+9+10)
B7: Kode | C7: Nama | D7: Nama | E7: Nomor | F7: Mata Uang | G7: Bank | H7: UP Tunai | I7: GUP | J7: LS Bendahara | K7: TUP | L7: Nomor | M7: Tanggal
A8: 1 | B8: 2 | C8: 3 | D8: 4 | E8: 5 | F8: 6 | G8: 7 | H8: 8 | I8: 9 | J8: 10 | K8: 11 | L8: 12 | M8: 13 | N8: 14 | O8: 15
A9: A | B9: Rekening Rutin
A10: 1 | B10: Kudam I/BB
A11: a | B11: xxxxxx | C11: Paldam-I/BB | D11: BPG xxx Paldam | E11: 1230000000 | F11: IDR | G11: Bank xxx | H11: xxx.xxx | I11: xxx.xxx | J11: xxx.xxx | K11: xxx.xxx | L11: S/ /xx/20xx | M11: dd-mm-yyyy | N11: dd-mm-yyyy | O11: xxx.xxx
A12: b | B12: xxxxxx | C12: Zidam-I/BB | D12: BPG xxx Zidam | E12: 1230000000 | F12: IDR | G12: Bank xxx | H12: xxx.xxx | I12: xxx.xxx | J12: xxx.xxx | K12: xxx.xxx | L12: S/ /xx/20xx | M12: dd-mm-yyyy | N12: dd-mm-yyyy | O12: xxx.xxx
A13: 2 | B13: Kudam II Swj
A14: a | B14: xxxxxx | C14: Rindam-II/SWJ | D14: BPG xxx Rindam | E14: 1230000000 | F14: IDR | G14: Bank xxx | H14: xxx.xxx | I14: xxx.xxx | J14: xxx.xxx | K14: xxx.xxx | L14: S/ /xx/20xx | M14: dd-mm-yyyy | N14: dd-mm-yyyy | O14: xxx.xxx
A15: b | B15: xxxxxx | C15: Paldam-II/SWJ | D15: BPG xxx Paldam | E15: 1230000000 | F15: IDR | G15: Bank xxx | H15: xxx.xxx | I15: xxx.xxx | J15: xxx.xxx | K15: xxx.xxx | L15: S/ /xx/20xx | M15: dd-mm-yyyy | N15: dd-mm-yyyy | O15: xxx.xxx
A16: dst
A17: B | B17: Rekening Pemerintah Lainnya (Hibah,BLU dan Lainnya)
A18: 1 | B18: Kudam I/BB
A19: a | B19: xxxxxx | C19: Paldam-I/BB | D19: RPL xxx PDH untuk 1234567 | E19: 1230000000 | F19: IDR | G19: Bank xxx | H19: - | I19: - | J19: - | K19: - | L19: S/ /xx/20xx | M19: dd-mm-yyyy | N19: dd-mm-yyyy | O19: xxx.xxx
A20: b | B20: xxxxxx | C20: Zidam-I/BB | D20: RPL xxx PDH untuk 1234567 | E20: 1230000000 | F20: IDR | G20: Bank xxx | H20: - | I20: - | J20: - | K20: - | L20: S/ /xx/20xx | M20: dd-mm-yyyy | N20: dd-mm-yyyy | O20: xxx.xxx
A21: 2 | B21: Kudam II/Swj
A22: a | B22: xxxxxx | C22: Rindam-II/SWJ | D22: RPL xxx PDH untuk 1234567 | E22: 1230000000 | F22: IDR | G22: Bank xxx | H22: - | I22: - | J22: - | K22: - | L22: S/ /xx/20xx | M22: dd-mm-yyyy | N22: dd-mm-yyyy | O22: xxx.xxx
A23: b | B23: xxxxxx | C23: Paldam-II/SWJ | D23: RPL xxx PDH untuk 1234568 | E23: 1230000000 | F23: IDR | G23: Bank xxx | H23: - | I23: - | J23: - | K23: - | L23: S/ /xx/20xx | M23: dd-mm-yyyy | N23: dd-mm-yyyy | O23: xxx.xxx
A24: dst
A25: (3) | B25: (4) | C25: (5) | D25: (6) | E25: (7) | F25: (8) | G25: (9) | H25: (10) | I25: (11) | J25: (12) | K25: (13) | L25: (14) | M25: (15) | N25: (16) | O25: (17) | P25: (14)
B27: JUMLAH (18)
L30: Kapusku TNI/Kadis Angkatan
L36: Nama
L37: Pangkat NRP/NIP
A40: LAPORAN SISA KAS
A41: UO KEMHAN
A42: BULAN………………..
A44: No | B44: Satker | D44: REKENING | H44: Peruntukan | L44: Surat Persetujuan | N44: Tanggal Transaksi Terakhir | O44: Saldo Akhir Bank (8+9+10)
B45: Kode | C45: Nama | D45: Nama | E45: Nomor | F45: Mata Uang | G45: Bank | H45: UP | J45: LS Bendahara | K45: TUP | L45: Nomor | M45: Tanggal
B46: 2 | C46: 3 | D46: 4 | E46: 5 | F46: 6 | G46: 7 | H46: 8 | J46: 9 | K46: 10 | L46: 11 | M46: 12 | N46: 13 | O46: 14 | P46: 12 | Q46: 13
A47: A | B47: Rekening Rutin
A48: 1 | B48: xxxxxx | C48: Baranahan Kemhan | D48: BPG 019 xxxxx | E48: 1230000000 | F48: IDR | G48: Bank xxx | H48: xxx.xxx | J48: xxx.xxxx | K48: xxx.xxx | L48: S/ /xx/20xx | M48: dd-mm-yyyy | N48: dd-mm-yyyy | O48: xxx.xxx
A49: 2 | B49: xxxxxx | C49: Ditjen Strahan Kemhan | D49: BPG 019 xxxxx | E49: 1230000000 | F49: IDR | G49: Bank xxx | H49: xxx.xxx | J49: xxx.xxxx | K49: xxx.xxx | L49: S/ /xx/20xx | M49: dd-mm-yyyy | N49: dd-mm-yyyy | O49: xxx.xxx
A50: 3 | B50: xxxxxx | C50: Puslapbinkuhan Kemhan | D50: BPG 019 xxxxx | E50: 1230000000 | F50: IDR | G50: Bank xxx | H50: xxx.xxx | J50: xxx.xxxx | K50: xxx.xxx | L50: S/ /xx/20xx | M50: dd-mm-yyyy | N50: dd-mm-yyyy | O50: xxx.xxx
A51: dst
A52: B | B52: Rekening Pemerintah Lainnya (Hibah,BLU dan Lainnya)
A53: 1 | B53: xxxxxx | C53: Baranahan Kemhan | D53: RPL 019 KS xxxx Untuk xxx | E53: 1230000000 | F53: USD | G53: Bank xxx | H53: - | J53: - | K53: - | L53: S/ /xx/20xx | M53: dd-mm-yyyy | N53: dd-mm-yyyy | O53: xxx.xxx
...
